## 1. 예외처리(exception handling)

### 1) 프로그램 오류

프그램이 실행 중 어떤 원인에 의해서 오작동을 하거나 비정상적으로 종료되는 경우가 있다. 이러한 결과를 초래하는 원인을 `프로그램 에러` 또는 `오류`라고 한다.

<br>

이를 발생시점에 따라 `컴파일 에러(compile-time error)` 와 `런타임 에러(runtime error)` 로 나눌 수 있는데, 글자 그대로 '컴파일 에러'는 컴파일 할 때 발생하는 에러이고 프로그램의 실행도중에 발생하는 에러를 '런타임 에러'라고 한다.

```
컴파일 에러 : 컴파일 시에 발생하는 에러
런타임 에러 : 실행 시에 발생하는 에러
논리적 에러 : 실행은 되지만, 의도와 다르게 동작하는 것
```

<br>

자바에서는 실행 시(runtime)발생할 수 있는 프로그램 오류를 '에러(error)'와 예외(exception)' 두 가지로 구분하였다.

```
에러(error)     : 프로그램 코드에 의해서 수습될 수 없는 심각한 오류
예외(exception) : 프로그램 코드에 의해서 수습될 수 있는 다소 미약한 오류
```

<br>

<br>

### 2) 예외 클래스의 계층구조

![picture](https://github.com/JaeYeon33/TIL/blob/main/JAVA/image/Untitled%209.png?raw=true)



<br>

상속계층도를 Exception클래스부터 도식화하면 다음과 같다.

<img src="https://github.com/JaeYeon33/TIL/blob/main/JAVA/image/Untitled%2010.png?raw=true" alt="picture" style="zoom:67%;" />

<br>

예외 클래스들은 다음과 같이 두 그릅으로 나눠질 수 있다.

1. Exception클래스와 그 자손들(RuntimeException과 자손들 제외)
2. RuntimeException클래스와 그 자손들

<br>

```
Exception클래스들        : 사용자의 실수와 같은 외적인 요인에 의해 발생하는 에러
RuntimeException클래스들 : 프로그래머의 실수로 발생하는 에러
```

<br>

<br>

### 3) 예외처리하기 - try~catch문

예외처리(exception handling)의

- 정의 - 프로그램 실행 시 발생할 수 있는 예외에 대비한 코드를 작성하는 것
- 목적 - 프로그램의 비정상 종료를 막고, 정상적인 실행상태를 유지하는 것

> 에러와 예외는 모두 실행 시(runtime) 발생하는 오류이다.

<br>

발생한 에러를 처리하지 못하면, 프로그램은 비정상적으로 종료되며, 처리되지 못한 예외(uncaught exception)은 JVM의 '예외처리기(UncaughtExceptionHandler)'가 받아서 예외의 원인을 화면에 출력한다.

```java
try {
		// 예외가 발생할 가능성이 있는 문장들을 넣는다.
} catch (Exception1 e1) {
		// Exception1이 발생했을 경우, 이를 처리하기 위한 문장을 적는다.
} catch (Exception2 e2) {
		// Exception2이 발생했을 경우, 이를 처리하기 위한 문장을 적는다.
} catch (ExceptionN eN) {
		// ExceptionN이 발생했을 경우, 이를 처리하기 위한 문장을 적는다.
}
```

하나의 try블럭 다음에는 여러 종류의 예외를 처리할 수 있도록 하나 이상의 catch블럭이 올 수 있으며, 이 중 발생한 예외의 종류와 일치하는 단 한 개의 catch블럭만 수행된다.

발생한 예외의 종류와 일치하는 catch블럭이 없으면 예외는 처리되지 않는다.

<br>

> if문과 달리, try블럭이나 catch블럭 내에 포함된 문장이 하나뿐이어도 괄호()를 생략할 수 없다.

<br>

<br>

### 4) try~catch문에서의 흐름

1. try블럭 내에서 예외가 발생한 경우

   - 발생한 예외와 일치하는 catch블럭이 있는지 확인한다.

   - 일치하는 catch블럭을 찾게 되면, 그 catch블럭 내의 문장들을 수행하고 전체 try-catch문을 빠져나가서 그 다음 문장을 계속해서 수행한다. 만일 일치하는 catch블럭을 차지 못하면, 예외는 처리되지 못한다.

2. try블럭 내에서 예외가 발생하지 않은 경우
   - catch블럭을 거치지 않고 전체 try~catch문을 빠져나가서 수행을 계속한다.


<br>

<br>

### 5) 예외의 발생과 catch블럭

catch블럭은 괄호()와 블럭{} 두 부분으로 나눠져 있는데, 괄호()내에는 처리하고자 하는 예외와 같은 타입의 참조변수 하나를 선언해야 한다. 예외가 발생하면, 발생한 예외에 해당하는 클래스의 인스턴스가 만들어진다. 

<br>

첫 번째 catch블럭부터 차례로 내려가면서 catch블럭의 괄호()내에 선언되 참조변수의 종류와 생성된 예외클래스의 인스턴스에 instanceof연산자를 이용해서 검사하게 되는데, 검사결과가 true인 catch블럭을 만날 때까지 검사는 계속된다.

검사결과가 true인 catch블럭을 찾게 되면 블럭에 있는 문장들을 모두 수행한 후에 try~catch문을 빠져나가고 예외는 처리되지만, 검사결과가 true인 catch블럭이 하나도 없으면 예외는 처리되지 않는다.

<br>

모든 예외 클래스는 Exception클래스의 자손이므로, catch블럭의 괄호()에 Exception클래스 타입의 참조변수를 선언해 놓으면 어떤 종류의 예외가 발생하더라도 이 catch 블럭에 의해서 처리된다.

<br>

<br>

### printStackTrace()와 getMessage()

```
printStackTrace() : 예외발생 당시의 호출스택(Call Stack)에 있었던 메서드의 정보와 예외 메세지를 화면에 출력한다.
getMessage()      : 발생한 예외클래스의 인스턴스에 저장된 메시지를 얻을 수 있다.
```

<br>

<br>

### 멀티 catch블럭

JDK1.7부터 여러 catch블럭을 `|` 기호를 이용해서 하나의 catch블럭으로 합칠 수 있게 되었으며, 이를 `멀티 catch블럭` 이라 한다. 멀티 catch블럭을 이용하면 중복된 코드를 줄일 수 있다. 그리고 `|` 기호로 연결할 수 있는 예외 클래스의 개수에는 제한이 없다.

> 멀티 catch블럭에 사용되는 `|` 는 논리 연산자가 아니라 기호이다.
> 

```java
try {
		...
} catch (Exception e) {
		e.printStackTrace();
} catch (ExceptionB e2) {
		e2.printStackTrace();
}
```

```java
try {
		...
} catch (ExceptionA | ExcepitonB e) {
		e.printStackTrace();
}
```

<br>

<br>

### 주의 !

멀티 catch블럭의 `|` 기호로 연결된 예외 클래스가 조상과 자손의 관계에 있다면 컴파일 에러가 발생한다.

```java
try {
		...
} catch (ParentException | ChildException e) { // 에러
		e.printStackTrace();
}
```

<br>

Why?

⇒ 두 예외 클래스가 조상과 자손의 관계에 있다면, 다음과 같이 조상 클래스만 써주는 것과 똑같이 때문.

불필요한 코드는 제거하라는 의미에서 에러가 발생하는 것

```java
try {
		...
} catch (ParentException e) {
		e.printStackTrace();
}
```

<br>

멀티 catch는 하나의 catch블럭으로 여러 예외를 처리하는 것이기 때문에, 발생한 예외를 멀티 catch블럭으로 처리하게 되었을 때, 멀티 catch블럭 내에서는 실제로 어떤 예외가 발생한 것인지 알 수 없다. 그래서 참조변수 e로 멀티 catch블럭에 `|` 기호로 연결된 예외 클래스들의 공통 분모인 조상 예외 클래스에 선언된 멤버만 사용 가능

```java
try {
		...
} catch (ExceptionA | ExceptionB e) {
		e.methodA();         // 에러. ExceptionA에 선언된 methodA()는 호출불가

		if (e instanceof ExceptionA) {
					ExceptionA e1 = (ExceptionA) e;
					e1.methodA();  // OK. ExceptionA에 선언된 메서드 호출가능
		} else {            // if(e instanceof ExceptionB)
					...
		}

		e.printStackTrace();
}
```

여러 catch블럭을 멀티 catch블럭으로 합치는 경우는 대부분 코드를 간단히 하는 정도의 수준일 것이므로 이러한 제약에 대해 너무 고민하지 않아도 된다.

<br>

<br>

### 6) 예외 발생시키기

**먼저 연산자 new를 이용해서 발생시키려는 예외 클래스의 객체를 만든 다음**

```java
Exception e = new Exception("고의로 발생시켰음");
```

**키워드 throw를 이용해서 예외를 발생시킨다.**

```java
throw e;
```

<br>

<br>

### 7) 메서드에 예외 선언하기

메서드에 예외를 선언하려면, 메서드의 선언부에 키워드 throws를 사용해서 메서드 내에서 발생할 수 있는 예외를 적어주기만 하면 된다. 그리고 예외가 여러 개일 경우네느 쉼표(.)로 구분한다.

```java
void method() throws Exception1, Exception2, ... ExceptionN {
		// 메서드의 내용
}
```

<u>이렇게 예외를 선언하면, 이 예외뿐만 아니라 그 자손타입의 예외까지도 발생할 수 있다는 점에 주의하자. 오버라이딩할 때는 단순히 선언된 예외의 개수가 아니라 상속관계까지 고려해야 한다.</u>

....

사실 예외를 메서드의 throws에 명시하는 것은 예외를 처리하는 것이 아니라, 자신(예외가 발생할 가능성이 있는 메서드)를 호출한 메서드에게 예외를 전다랗여 예외처치를 떠맡기는 것이다.

예외를 전달받은 메서드가 또다시 자신을 호출한 메서드에게 전달할 수 있으며, 이런 식으로 계속 호출스택에 있는 메서드들을 따라 전달되다가 제일 마지막에 있는 main메서드에서도 예외가 처리되지 않으면, main메서드마저 종료되어 프로그램이 전체가 종료된다.

<br>

<br>

### 8) finally블럭

finally블럭은 예외의 발생여부에 상관없이 실행되어야할 코드를 포함시킬 목적으로 사용된다. try-catch문의 끝에 선택적으로 덧붙여 사용할 수 있으며, try-catch-finally의 순서로 구성된다.

```java
try {
		// 예외가 발생할 가능성이 있는 문장들을 넣는다.
} catch (Exception1 e1) {
		// 예외처리를 위한 문장을 적는다.
} finally {
		// 예외의 발생여부에 관계없이 항상 수행되어야하는 문장들을 넣는다.
		// finally블럭은 try-catch문의 맨 마지막에 위치해야한다.
}
```

- 예외가 발생한 경우 : try → catch → finally
- 예외가 발생하지 않은 경우 : try → finally

<br>

<br>

### 9) 자동 자원 반환 - try-with-resources문

JDK1.7부터 try-with-resources문이라는 try-catch문의 변형이 새로 추가되었다.

주로 입출력에 사용되는 클래스 중에서는 사용한 후에 꼭 닫아 줘야 하는 것들이 있다.

그래야 사용했던 자원(resources)이 반환되기 때문이다.

```java
try {
		fis = new FIleInputStream("score.dat");
		dis = new DataInputStream(fis);
				...
} catch (IOException ie) {
		ie.printStackTrace();
} finally {
		dis.close();  // 작업 중에 예외가 발생하더라도, dis가 닫히도록 finally블럭에 넣음
}
```

<br>

별 문제가 없어보이지만, 진짜 문제는 close()가 예외를 발생시킬 수 있다는데 있다. 그래서 이렇게 해야 올바른 것이 된다.

```java
try {
		fis = new FileInputStream("score.dat");
		dis = new DataInputStream(fis);
				...
} catch (IOExcepiton ie) {
		ie.printStackTrace();
} finally {
		try {
				if (dis != null)
						dis.close();
		} catch (IOException ie) {
				ie.printStackTrace();
		}
}
```

<br>

finally블럭 안에 try-catch문을 추가해서 close()에서 발생할 수 있는 에러를 처리하도록 변경했는데, 코드가 복잡해져서 별로 보기에 좋지 않다. 더 나쁜 것은 try블럭과 finally블럭에서 모두 예외가 발생하면, try블럭의 예외는 무시된다는 것이다.

이러한 점을 개선하기 위해서 try-catch-resources문이 추가된 것이다.

```java
// 괄호()안에 두 문장 이상 넣을 경우 ';'로 구분했다.
try (FileInputStream fis = new FileInputStream("score.dat");
		DataInputStream dis = new DataInputStream(fis)) {

		while(true) {
				score = dis.readInt();
				System.out.println(score);
				sum += score;
		}
} catch (EOFException e) {
		System.out.println("점수의 총합은 " + sum + "입니다.");
} catch (IOException ie) {
		ie.printStackTrace();
}
```

<br>

try-with-resources문의 괄호()안에 객체를 생성하는 문장을 넣으면, 이 객체는 따로 close()를 호출하지 않아도 try블럭을 벗어나는 순간 자동적으로 close()가 호출된다. 그 다음에 catch블럭 또는 finally블럭이 수행된다.

> try블럭의 괄호()안에 변수를 선언하는 것도 가능하며, 선언된 변수는 try블럭 내에서만 사용할 수 있다.
> 

<br>

이처럼 try-with-resources문에 의해 자동으로 객체의 close()가 호출될 수 있으려면, 클래스가 AutoCloseable이라는 인터페이스를 구현한 것이어야만 한다.

```java
public interface AutoCLoseable {
		void close() throws Exception;
}
```

위의 인터페이스는 각 클래스에서 적절히 자원 반환작업을 하도록 구현되어 있다.

But, 코드를 보면 close()도 Exception을 발생시킬 수 있다. 만일 자동 호출된 close()에서 예외가 발생하면 어떻게 될까

<br>

<br>

### 10) 사용자정의 예외 만들기

기존의 정의된 예외 클래스 외에 필요에 따라 프로그래머가 새로운 예외 클래스를 정의하여 사용할 수 있다.

보통 Exception클래스 또는 RuntimeException클래스로부터 상속받아 클래스를 만들지만, 필요에 따라서 알맞은 예외 클래스를 선택할 수 있다.

```java
class MyException extends Exception {
		MyException(String msg) {  // 문자열 매개변수로 받는 생성자
				super(msg);            // 조상인 Exception클래스의 생성자를 호출
		}
}
```

<br>

사용자정의 예외 클래스도 메시지를 저장할 수 있으려면, String을 매개변수로 받는 생성자를 추가해주어야 한다.

```java
class MyException extends Exception {
		// 에러 코드 값을 저장하기 위한 필드를 추가 했다.
		private final int ERR_CODE;  // 생성자를 통해 초기화 한다.

		MyException(String msg, int errCode) {  // 생성자
				super(msg);
				ERR_CODE = errCode;
		}

		MyException(String msg) {  // 생성자
				this(msg, 100);        // ERR_CODE를 100(기본값)으로 초기화한다.
		}

		public int getErrCode() {  // 에러 코드를 얻을 수 있는 메서드도 추가했다.
				return ERR_CODE;       // 이 메서드는 주로 getMessage()와 함께 사용될 것이다.
		}
}
```

<br>

이 코드는 메시지뿐만 아니라 에러코드 값도 저장할 수 있도록 ERR_CODE와 getErrCode()를 MyException클래스의 멤버로 추가했다.

MyException이 발생했을 때, catch블럭에서 getMessage()와 getErrCode()를 사용ㅇ해서 에러코드와 메시지를 모두 얻을 수 있을 것이다.

<br>

기존의 예외 클래스는 Exception을 상속받아서 'checked예외'로 작성하는 경우가 많았지만, 요즘은 예외처리를 선택적으로 할 수 있도록 RuntimeException을 상속받아서 작성하는 쪽으로 바뀌어가고 있다.

<br>

<br>

### Why?

⇒ 'checked예외'는 반드시 예외처리를 해주어야 하기 떄문에 예외처리가 불필요한 경우에도 try-catch문을 넣어서 코드가 복잡해지기 떄문이다.

<br>

그래서 필요에 따라 예외처리의 여부를 선택할 수 있는 'unchecked예외'가 강제적인 'checked예외'보다 더 환영받고 있다.

<br>

<br>

### 11) 예외 되던지기(exception re-throwing)

한 메서드에서 발생할 수 있는 예외가 여럿인 경우, 몇 개는 try-catch문을 통해서 메서드 내에서 자체적으로 처리하고, 그 나머지는 선언부에 지정하여 호출한 메서드에서 처리하도록 함으로써, 양쪽에서 나눠서 처리되도록 할 수 있다. 단 하나의 예외에 대해서도 예외가 발생한 메서드와 호출한 메서드, 양쪽에서 처리하도록 할 수 있다.

이것은 예외를 처리한 후에 인위적으로 다시 발생시키는 방법을 통해서 가능한데, 이것을 '예외 되던지기(exception re-throwing)'이라고 한다.

<br>

<br>

먼저 예외가 발생할 가능성이 있는 메서드에서 try-catch문을 사용해서 예외를 처리해주고 catch문에서 필요한 작업을 행한 후에 throw문을 사용해서 예외를 다시 발생시킨다. 다시 발생한 예외는 이 메서드를 호출한 메서드에게 전달되고 호출한 메서드의 try-catch문에서 예외를 또다시 처리한다.

⇒ 하나의 예외에 대해서 발생한 메서드와 이를 호출한 메서드 양쪽 모두에서 처리해줘야 할 작업이 있을 때 사용. 

<br>

<br>

### !주의

예외가 발생할 메서드에서는 try-catch문을 사용해서 예외처리를 해줌과 동시에 메서드의 선언부에 발생할 예외를 throws에 지정해줘야 한다는 것

<br>

<br>

### 12) 연결된 예외(chained exception)

한 예외가 다른 예외를 발생시킬 수도 있다. 예를 들어 A가 예외 B를 발생시켰다면,

A를 B의 '원인 예외(cause exception)'라고 한다.

```java
try {
		startInstall();   // SpaceException 발생
		copyFiles();
} catch (SpaceException e) {
		InstallException ie = new InstallException("설치중 예외발생");
		ie.initCause(e);  // InstallException의 원인 예외를 SpaceException으로 지정
		throw ie;         // InstallException을 발생시킨다.
} catch (MemoryException me) {
		...
```

<br>

InstallException을 생성한 후에, ininCause()로 SpaceException을 InstallException의 원인 예외로 등록한다. 그리고 'throw'로 이 예외를 던진다.

initCause()는 Exception클래스의 조상인 Throwable클래스에 정의되어 있기 때문에 모든 예외에서 사용가능하다.

```java
Throwable initCause (Throwable cause) : 지정한 예외를 원인 예외로 등록
Throwable getCause()                  : 원인 예외를 반환
```

<br>

<br>

### 발생한 예외를 원인 예외로 등록해서 다시 예외를 발생시키는가?

⇒ 여러가지 예외를 하나의 큰 분류의 예외로 묶어서 다루기 위해서

```java
try {
		startInstall();              // SpaceException 발생
		copyFiles();
} catch (InstallException e) {  // InstallException은
		e.printStackTrace();        // spaceException과 MemoryException의 조상
}
```

<br>

예외가 원인 예외를 포함할 수 있게 하면 된다. 이렇게 하면 두 예외는 상속이 아니여도 된다.

```java
public class Throwable implements Serializable {
		...
		private Throwable cause = this;  // 객체 자신(this)을 원인 예외로 등록
		...
}
```

<br>

또 다른 이유 : checked예외 → unchecked예외로 바꿀 수 있도록 하기 위해

```java
static void startInstall() throws SpaceException, MemoryException {
		if (!enoughSpace())     // 충분한 설치 공간이 없으면...
			throw new SpaceException("설치할 공간이 부족합니다.");
		
		if (!enoughMemory())    // 충분한 메모리가 없으면...
			throw new MemoryException("메모리가 부족합니다.");
}
```

<br>

→

<br>

```java
static void startInstall() throw SpaceException {
		if (!enoughSpace())     // 충분한 설치 공간이 없으면...
			throw new SpaceException("설치할 공간이 부족합니다.");
		
		if (!enoughMemory())    // 충분한 메모리가 없으면...
			throw new RuntimException(new MemoryException("메모리가 부족합니다."));
} // end of startInstall
```

<br>

MemoryException은 Exception의 자손이므로 반드시 예외를 처리해야하는데, 이 예외를 RuntimeException으로 감싸버렸기 때문에 unchecked예외가 되었다. 그래서 더 이상 startInstall()의 선언부에 MemoryException을 선언하지 않아도 된다. 참고로 위의 코드에서는 initCause()대신 RumetimeException의 생성자를 사용

```java
RuntimeException(Throwable cause) // 원인 예외를 등록하는 생성자
```